你好，我是Tony Bai。

在上一节中，我们开始学习函数设计的相关知识，学习了如何基于Go函数的多返回值机制进行函数错误值构造方式的设计，你还记得那几种错误值构造与处理的策略吗？当然，良好的函数设计不仅仅要包含错误设计，函数的健壮性与简洁优雅也是我们在函数设计过程中要考虑的问题。

健壮的函数意味着，无论调用者如何使用你的函数，你的函数都能以合理的方式处理调用者的任何输入，并给调用者返回预设的、清晰的错误值。即便你的函数发生内部异常，函数也会尽力从异常中恢复，尽可能地不让异常蔓延到整个程序。而简洁优雅，则意味着函数的实现易读、易理解、更易维护，同时简洁也意味着统计意义上的更少的bug。

这一节课，我们就将继续我们的函数设计之旅，聚焦在健壮与简洁这两方面，我们需要重点关注的内容。

我们先从健壮性开始。

## 健壮性的“三不要”原则

函数的健壮性设计包括很多方面，首先就有最基本的“三不要”原则，我们简单来分析一下。

**原则一：不要相信任何外部输入的参数。**

函数的使用者可能是任何人，这些人在使用函数之前可能都没有阅读过任何手册或文档，他们会向函数传入你意想不到的参数。因此，为了保证函数的健壮性，函数需要对所有输入的参数进行合法性的检查。一旦发现问题，立即终止函数的执行，返回预设的错误值。
<div><strong>精选留言（30）</strong></div><ul>
<li><img src="https://static001.geekbang.org/account/avatar/00/13/7b/bd/ccb37425.jpg" width="30px"><span>进化菌</span> 👍（23） 💬（2）<div>panic 恐慌，慌慌张张的抛出异常；recover 恢复，淡定还有事情要做，先别退出；defer 延迟，晚点要做的事情不能忘……</div>2021-12-06</li><br/><li><img src="https://static001.geekbang.org/account/avatar/00/12/1d/dd/95cdb4d8.jpg" width="30px"><span>helloxiaomin</span> 👍（20） 💬（1）<div>defer的使用技巧：1）defer要在panic之前，才能执行；2）defer内部的recover只能捕获当前协程的Panic，不能跨协程执行；3）recover只能在defer中调用才能生效。暂时想到这些</div>2021-12-07</li><br/><li><img src="https://static001.geekbang.org/account/avatar/00/11/53/a8/abc96f70.jpg" width="30px"><span>return</span> 👍（15） 💬（5）<div>老师讲的太好了，
再请教一下老师， panic应该在什么场景下使用，
感觉平时 业务代码 使用 err足够，没有使用panic的场景，
文中举例的 http server比较合适， 但是json encode，虽然官方用了panic，但是个人感觉 使用err也没毛病， 传入的 json串 有问题嘛，就是 入参校验err呗。 
所以 get 不到 什么情况下用 panic。</div>2021-12-06</li><br/><li><img src="https://static001.geekbang.org/account/avatar/00/20/1e/18/9d1f1439.jpg" width="30px"><span>liaomars</span> 👍（11） 💬（3）<div>看了官方标准库的defer说明，发现一个tips是：可以跟踪函数的执行过程</div>2021-12-06</li><br/><li><img src="https://static001.geekbang.org/account/avatar/00/0f/57/4f/6fb51ff1.jpg" width="30px"><span>奕</span> 👍（8） 💬（6）<div>请教一个非课程的问题：
v := [...]int{1: 2, 3: 4}
fmt.Println(len(v)) 

这里为什么打印出来的 长度是 4呢？</div>2021-12-07</li><br/><li><img src="https://static001.geekbang.org/account/avatar/00/14/9d/a4/e481ae48.jpg" width="30px"><span>lesserror</span> 👍（6） 💬（2）<div>感谢 Tony Bai 老师关于defer的深入讲解，不过我想问一下，在for中使用defer函数，编辑器会提示可能造成资源泄露，能大致说明一下这块儿的知识吗？</div>2021-12-07</li><br/><li><img src="https://static001.geekbang.org/account/avatar/00/1a/f3/95/77628ed0.jpg" width="30px"><span>van</span> 👍（3） 💬（1）<div>panic作为断言使用，上一层的调用者还是需要自己recover回来吧，不然这个调用链会最终传到main函数</div>2022-04-28</li><br/><li><img src="https://static001.geekbang.org/account/avatar/00/27/af/fd/a1708649.jpg" width="30px"><span>ゝ骑着小车去兜风。</span> 👍（3） 💬（4）<div>老师你好，没太明白闭包的原理，想不明白为什么输出的是4，请帮忙解答下</div>2022-01-06</li><br/><li><img src="https://static001.geekbang.org/account/avatar/00/29/b0/d3/200e82ff.jpg" width="30px"><span>功夫熊猫</span> 👍（3） 💬（1）<div>defer数据库的开关。锁的申请释放。TCP的连接和断开之类的</div>2021-12-11</li><br/><li><img src="https://static001.geekbang.org/account/avatar/00/1f/91/28/f2dcbbfe.jpg" width="30px"><span>宋世杰</span> 👍（3） 💬（4）<div>Defer函数被放在一个不同于主函数的函数栈中吗？ 是用slice实现的吗？</div>2021-12-06</li><br/><li><img src="https://static001.geekbang.org/account/avatar/00/13/9c/85/d9614715.jpg" width="30px"><span>Felix</span> 👍（2） 💬（1）<div>defer benchmark的例子中，函数sum有返回值，所有defer的时候放在闭包里面，如果函数sum没有返回值，可以直接放在defer后面defer sum()，我做了一下benchmark，发现还是放闭包里面比较快，go语言对闭包有什么优化吗，感觉用闭包会多压一次栈，但是反而更快，老师能解答一下吗？
&#47;&#47; defer_test.go
package main

import &quot;testing&quot;

func sum(max int) {
    total := 0
    for i := 0; i &lt; max; i++ {
        total += i
    }
}

func fooWithDeferNoClosure() {
	defer sum(10)
}

func fooWithDefer() {
    defer func() {
        sum(10)
    }()
}
func fooWithoutDefer() {
    sum(10)
}

func BenchmarkFooWithDeferNoClosure(b *testing.B) {
    for i := 0; i &lt; b.N; i++ {
        fooWithDeferNoClosure()
    }
}

func BenchmarkFooWithDefer(b *testing.B) {
    for i := 0; i &lt; b.N; i++ {
        fooWithDefer()
    }
}
func BenchmarkFooWithoutDefer(b *testing.B) {
    for i := 0; i &lt; b.N; i++ {
        fooWithoutDefer()
    }
}

benchmark结果：
$ go test -bench . defer_test.go
goos: linux
goarch: amd64
cpu: Intel Core Processor (Broadwell, IBRS)
BenchmarkFooWithDeferNoClosure-2   	67386957	        18.59 ns&#47;op
BenchmarkFooWithDefer-2                  	80693001	        15.45 ns&#47;op
BenchmarkFooWithoutDefer-2             	100000000	11.03 ns&#47;op
PASS
ok  	command-line-arguments	3.665s</div>2022-05-15</li><br/><li><img src="https://static001.geekbang.org/account/avatar/00/0f/4c/12/f0c145d4.jpg" width="30px"><span>Rayjun</span> 👍（2） 💬（2）<div>老师，咨询一个问题，panic 无法跨 goroutine 捕获，这个是为什么呢？</div>2022-03-14</li><br/><li><img src="https://static001.geekbang.org/account/avatar/00/28/2e/0c/b6180a5f.jpg" width="30px"><span>风铃</span> 👍（2） 💬（1）<div>自己以前写代码，总是在panic把错误信息包进去
if !=nil{
    panic(fmt.Errorf(&quot;err is:%s\n&quot;,err))
}</div>2022-03-05</li><br/><li><img src="http://thirdwx.qlogo.cn/mmopen/vi_32/pibibkbticCqnwDJkluy5QAWibesJ7vxLbQIG5sewicnjyjYFD9S4Oq9XYxxmjWTQTtFaNeYN6MpXwNAqfe8vUib21PA/132" width="30px"><span>Geek_7jzyrf</span> 👍（2） 💬（2）<div>老师，在  “注意 defer 关键字后面表达式的求值时机” 这个知识点，
 func foo3(){
	 for i :=0; i &lt;=3; i++{
		 defer func(){  
			 fmt.Println(i)

		 }()
	 }
 }
输出结果为啥是4？ i 最大应该只能取到3吧？没看明白，希望老师进一步解答下！</div>2021-12-29</li><br/><li><img src="https://static001.geekbang.org/account/avatar/00/11/1d/de/62bfa83f.jpg" width="30px"><span>aoe</span> 👍（2） 💬（1）<div>在 main 函数开始加上这样的代码，可以从 panic 中无限复活了
defer func() {
	if e := recover(); e != nil {
		fmt.Println(&quot;recover the panic:&quot;, e)
	}
}()</div>2021-12-08</li><br/><li><img src="https://static001.geekbang.org/account/avatar/00/29/bb/e0/c7cd5170.jpg" width="30px"><span>Bynow</span> 👍（2） 💬（6）<div>我用的goland ，文中更新后的bar代码：我的编辑器终端输出是
call main
call foo
call bar
exit foo
exit main
recover the panic: panic occurs in bar

但是我打断点调试的确是按照老师的那样去执行和输出的，这是怎么回事？</div>2021-12-07</li><br/><li><img src="https://static001.geekbang.org/account/avatar/00/29/00/7a/791d0f5e.jpg" width="30px"><span>大年糕</span> 👍（1） 💬（1）<div>把defer作为析构函数使用?</div>2023-05-25</li><br/><li><img src="" width="30px"><span>Geek_73c432</span> 👍（1） 💬（1）<div>有没有可能 deferred 函数本身执行的时候会引发异常（panic）呢？

经测试（go version go1.20.2 linux&#47;amd64）在这种情况下，其他已经注册的 deferred 函数还会正常执行，例如这个捕获 panic 并恢复的 deferred 函数

func deferTest() {
        &#47;&#47; func1
	defer func() {
		if err := recover(); err != nil {
			fmt.Println(&quot;recover the panic: &quot;, err)
		}
	}()
	defer func() {
		fmt.Println(&quot;exit... with panic&quot;)
		panic(&quot;whatever...&quot;)
	}()
}

为啥已经触发 panicking，func1 还会执行呢？</div>2023-05-19</li><br/><li><img src="" width="30px"><span>Geek_0d5d37</span> 👍（1） 💬（2）<div>作者回复: 首先确认一下对for语义的理解。针对for i := 0; i &lt;= 3; i++ {}循环， 当i=3时，for进入循环体，然后执行后置语句i++，之后i的值为4. 然后再判断循环条件i&lt;=3，不满足，for循环结束。于是i的最终值就是4。

defer执行时，i是4，闭包引用的是同一个i，所以都输出4。

老师您好。 上面是您回答的一个问题，基于这个问题我有点不理解

既然defer 后面的函数是在执行defer的时候注册并求值，那闭包引用的也是当前环境的变量。 也就是for 每次执行循环体时注册的闭包环境， 最后延迟调用也是注册时对应的闭包环境的i值， 而不是循环判断不满足条件结束循环后运行的环境。  这是不明白的点，麻烦老师有空时讲解下</div>2023-03-27</li><br/><li><img src="https://static001.geekbang.org/account/avatar/00/0f/e5/4f/731ef2c1.jpg" width="30px"><span>geektime_zpf</span> 👍（1） 💬（1）<div>&quot;defer 关键字后面的表达式，是在将 deferred 函数注册到 deferred 函数栈的时候进行求值的&quot;
老师你好，请问deffered函数注册到函数栈的时机具体是什么？</div>2023-01-04</li><br/><li><img src="https://thirdwx.qlogo.cn/mmopen/vi_32/LN7qpRLUGO2IHMnbDuF4YEsd9PxdFHAumWsHE8AhibeQUryIfgsQZ3JIZswVcCRkVSaelhFiatCZ6wpQFoLBLVFA/132" width="30px"><span>宥晓</span> 👍（1） 💬（1）<div>go 的版本1.18.3, defer的性能下降了，这是有什么大的变动吗？

go test -bench . defer_test.go

goos: darwin
goarch: amd64
cpu: Intel(R) Core(TM) i5-1038NG7 CPU @ 2.00GHz
BenchmarkFooWithDefer-8         191820978                6.144 ns&#47;op
BenchmarkFooWithoutDefer-8      527924869                2.245 ns&#47;op
PASS
ok      command-line-arguments  3.643s
</div>2022-06-19</li><br/><li><img src="https://static001.geekbang.org/account/avatar/00/14/0a/da/dcf8f2b1.jpg" width="30px"><span>qiutian</span> 👍（1） 💬（1）<div>我的vscode静态检查出：func zoo is unused (U1000)go-staticcheck
但是通过build 构建和 运行是可以得到和目标相同的结果的</div>2022-06-03</li><br/><li><img src="https://thirdwx.qlogo.cn/mmopen/vi_32/tVrFvKWxQAuL7DE911OmlcqnfEkBnx14dBmCdI8eOx6ziaQB4Pgml65tcIDO4ePfW5yPTyAxGovYQmXLZHAPe2Q/132" width="30px"><span>Junior Programmer</span> 👍（1） 💬（0）<div>老师您好,对于defer参数求值时机有一点疑惑，func foo1() { for i := 0; i &lt;= 3; i++ { defer fmt.Println(i) }}这个i参数，传入到fmt.Printlin中不是应该是1开始的吗，然后根据defer执行时先进后出原则,应该是4,3,2,1,但是我在本地运行的是3,2,1,0，也就是说defer参数传入的时机，还没有执行i++，这个是什么原因呢？</div>2022-05-17</li><br/><li><img src="https://static001.geekbang.org/account/avatar/00/11/12/a8/8aaf13e0.jpg" width="30px"><span>mikewoo</span> 👍（1） 💬（1）<div>老师，这篇文章给了我很多新的理解，收获满满。课程中“当 foo3 返回后，deferred 函数被调度执行时，上述压入栈的 deferred 函数将以 LIFO 次序出栈执行。匿名函数会以闭包的方式访问外围函数的变量 i，并通过 Println 输出 i 的值，此时 i 的值为 4。”为什么输出的结果都是4，这个不是很理解，能否帮忙再解释一下，谢谢。</div>2022-04-27</li><br/><li><img src="https://static001.geekbang.org/account/avatar/00/18/4b/d7/f46c6dfd.jpg" width="30px"><span>William Ning</span> 👍（1） 💬（1）<div>大卡，继续学习，思考中～～</div>2022-03-24</li><br/><li><img src="https://static001.geekbang.org/account/avatar/00/11/bd/65/fbdf4fc1.jpg" width="30px"><span>羊羊</span> 👍（1） 💬（1）<div>对于自定义的函数或方法，defer 可以给与无条件的支持，但是对于有返回值的自定义函数或方法，返回值会在 deferred 函数被调度执行的时候被自动丢弃。  是指defer语句后面的函数的返回值会被丢弃么？下面匿名函数的返回值2没有接受者，return了也没啥用，可以这么理解么？
func bar() {
	defer func() int {
		fmt.Println(&quot;defer func in bar&quot;)
		return 2
	}()
	fmt.Println(&quot;call bar&quot;)
	fmt.Println(&quot;exit bar&quot;)
}</div>2021-12-27</li><br/><li><img src="https://static001.geekbang.org/account/avatar/00/14/26/27/eba94899.jpg" width="30px"><span>罗杰</span> 👍（1） 💬（1）<div>关于 defer 我还要好好看看，一直都没怎么理解透彻</div>2021-12-06</li><br/><li><img src="" width="30px"><span>Geek_73c432</span> 👍（0） 💬（1）<div>老师好，我在阅读标准库的一些例子的时候发现，当 caller 接收到一个 error 时，惯用法是使用 log.Fatal&#47;log.Fatalf 打印这个 error，这将导致执行 os.Exit(1)，这样不会执行 deferred 函数。例如：

ctx, stop := signal.NotifyContext(context.Background(), os.Interrupt)
defer stop()

p, err := os.FindProcess(os.Getpid())
if err != nil {
  log.Fatal(err)
}

...

这段代码中，如果 os.FindProcess 调用返回 error，stop 函数将不会被执行。如果换成 log.Panicf(err) 的话 stop 函数会被执行。

但是这种场景使用 Panic 有点混淆错误和异常的概念

你怎么看待这两种处理方式？更推荐哪一种呢？</div>2024-08-31</li><br/><li><img src="https://static001.geekbang.org/account/avatar/00/14/0f/c2/de176336.jpg" width="30px"><span>山深沾衣</span> 👍（0） 💬（1）<div>func foo3() {
	for i := 0; i &lt;= 3; i++ {
		defer func() {
			fmt.Println(i)
		}()
	}
}

这个函数输出的结果是3 2 1 0 怎么和老师的不一样呢</div>2024-06-28</li><br/><li><img src="https://static001.geekbang.org/account/avatar/00/19/cc/70/64045bc0.jpg" width="30px"><span>人言有力</span> 👍（0） 💬（1）<div>本节核心介绍了panic、recover、defer三个关键字对程序异常和健壮性的帮助
1. panic是手动触发程序崩溃，常用于断言
2.recover是恢复panic，但是需要在defer关键字后，defered函数会在本体函数退出前按LIFO声明的顺序执行
3.defer是有性能开销的，但是很适合作为资源释放和异常处理，类似JAVA的finally。但是不要滥用，一些checked exception应该当作错误进行返回值处理</div>2024-05-16</li><br/>
</ul>