你好，我是朱晔。今天，我来和你聊聊异常处理容易踩的坑。

应用程序避免不了出异常，捕获和处理异常是考验编程功力的一个精细活。一些业务项目中，我曾看到开发同学在开发业务逻辑时不考虑任何异常处理，项目接近完成时再采用“流水线”的方式进行异常处理，也就是统一为所有方法打上try…catch…捕获所有异常记录日志，有些技巧的同学可能会使用AOP来进行类似的“统一异常处理”。

其实，这种处理异常的方式非常不可取。那么今天，我就和你分享下不可取的原因、与异常处理相关的坑和最佳实践。

## 捕获和处理异常容易犯的错

“统一异常处理”方式正是我要说的第一个错：**不在业务代码层面考虑异常处理，仅在框架层面粗犷捕获和处理异常**。

为了理解错在何处，我们先来看看大多数业务应用都采用的三层架构：

- Controller层负责信息收集、参数校验、转换服务层处理的数据适配前端，轻业务逻辑；
- Service层负责核心业务逻辑，包括各种外部服务调用、访问数据库、缓存处理、消息处理等；
- Repository层负责数据访问实现，一般没有业务逻辑。

![](https://static001.geekbang.org/resource/image/2f/61/2f2cfbd86efd3bc140400bcaf2985361.png?wh=1304%2A1284)

每层架构的工作性质不同，且从业务性质上异常可能分为业务异常和系统异常两大类，这就决定了很难进行统一的异常处理。我们从底向上看一下三层架构：
<div><strong>精选留言（30）</strong></div><ul>
<li><img src="https://static001.geekbang.org/account/avatar/00/13/26/38/ef063dc2.jpg" width="30px"><span>Darren</span> 👍（106） 💬（16）<div>这篇文章收获很大，因为我们现在的系统就是用的统一异常处理，使用的就是老师提到的兜底异常，就是简单的分为业务异常和非业务异常，提示语不同而已。
试着回答下问题：
第一个问题：
肯定是以finally语句块为准。
原因：首先需要明白的是在编译生成的字节码中，每个方法都附带一个异常表。异常表中的每一个条目代表一个异常处理器，并且由 from 指针、to 指针、target 指针以及所捕获的异常类型构成。这些指针的值是字节码索引（bytecode index，bci），用以定位字节码。其中，from 指针和 to 指针标示了该异常处理器所监控的范围，例如 try 代码块所覆盖的范围。target 指针则指向异常处理器的起始位置，例如 catch 代码块的起始位置；
当程序触发异常时，Java 虚拟机会从上至下遍历异常表中的所有条目。当触发异常的字节码的索引值在某个异常表条目的监控范围内，Java 虚拟机会判断所抛出的异常和该条目想要捕获的异常是否匹配。如果匹配，Java 虚拟机会将控制流转移至该条目 target 指针指向的字节码。如果遍历完所有异常表条目，Java 虚拟机仍未匹配到异常处理器，那么它会弹出当前方法对应的 Java 栈帧，并且在调用者（caller）中重复上述操作。在最坏情况下，Java 虚拟机需要遍历当前线程 Java 栈上所有方法的异常表。所以异常操作是一个非常耗费性能的操作；
finally 代码块的原理是复制 finally 代码块的内容，分别放在 try-catch 代码块所有正常执行路径以及异常执行路径的出口中。所以不管是是正常还是异常执行，finally都是最后执行的，所以肯定是finally语句块中为准。

第二个问题：
IllegalArgumentException：不合法的参数异常，比如说限制不能为空或者有指定的发小范围，调用方没有按照规定传递参数，就可以抛出这个异常；
IllegalStateException：如果有状态流转的概念在里面（比如状态机），状态只能从A-&gt;B-&gt;C,若状态直接从A-&gt;C,就可以抛出该异常；
UnsupportedOperationException：不支持该操作异常，比如非抽象父类中有个方法，子类必须实现，父类中的方法就可以抛出次异常。老师在集合坑中提到的Arrays.asList 返回的 List 并不是我们期望的 java.util.ArrayList，而是 Arrays 的内部类 ArrayList。ArrayList 内部类继承自 AbstractList 类，并没有覆写父类的 add 方法，而父类中 add 方法的实现，就是抛出 UnsupportedOperationException。
</div>2020-04-05</li><br/><li><img src="https://static001.geekbang.org/account/avatar/00/14/17/3b/37bcd31e.jpg" width="30px"><span>扎紧绷带</span> 👍（26） 💬（1）<div>老师，为了便于定位异常请求bug，我希望url请求后端出现异常后，框架拦截打印出请求的参数信息，因为body里的参数在流中，只能消费一次，想要在出错后打印，必须要提前复制出一份保存。老师有什么好的实践吗？</div>2020-07-11</li><br/><li><img src="http://thirdwx.qlogo.cn/mmopen/vi_32/bvj76PmeUvW8kokyu91IZWuRATKmabibDWbzAj2TajeEic7WvKCJOLaOh6jibEmdQ36EO3sBUZ0HibAiapsrZo64U8w/132" width="30px"><span>梦倚栏杆</span> 👍（18） 💬（5）<div>遇到一个坑(也可以说不理解)，和该篇文章没关系，反馈一下

mysql 占位符问题
prepare sqltpl from &#39;select id,name from table1 where id in (?)&#39;;
set @a=&#39;1,2,3,4,5,6,7,8,9&#39;;
execute  sqltpl using @a;

结果：只输出第一条符合条件的记录

prepare sqltpl from &#39;select name from table1 where name in (?)&#39;;
set @a=&#39;zhangsan,lisi,wangwu&#39;;
execute  sqltpl using @a;
结果没有记录</div>2020-04-06</li><br/><li><img src="https://static001.geekbang.org/account/avatar/00/10/3b/36/2d61e080.jpg" width="30px"><span>行者</span> 👍（15） 💬（5）<div>老师，关于 千万别把异常定义为静态变量，麻烦分析下为什么cancelOrderRight抛出的异常信息指向createOrderWrong所在的行~</div>2020-04-04</li><br/><li><img src="https://static001.geekbang.org/account/avatar/00/10/3b/36/2d61e080.jpg" width="30px"><span>行者</span> 👍（14） 💬（1）<div>IllegalArgumentException: 入参错误，比如参数类型int输入string。
IllegalStateException: 状态错误，比如订单已经支付完成，二次请求支付接口。
UnsupportedOperationException: 不支持操作错误，比如对一笔不能退款的订单退款。
其他异常
SecurityException: 权限错误，比如未登陆用户调用修改用户信息接口。</div>2020-04-04</li><br/><li><img src="https://static001.geekbang.org/account/avatar/00/10/1c/6e/6c5f5734.jpg" width="30px"><span>终结者999号</span> 👍（8） 💬（2）<div>关于行者的问题，请老师再解释一下可以吗？貌似没有看懂那个回复，什么叫一次性fillstacktrace？</div>2020-04-05</li><br/><li><img src="https://static001.geekbang.org/account/avatar/00/11/ce/79/673f4268.jpg" width="30px"><span>小杰</span> 👍（3） 💬（1）<div>老师，看不懂那个异常定义为静态变量的例子，异常打印的是堆栈信息，堆栈信息必须是对象是这个意思吗？</div>2020-04-05</li><br/><li><img src="http://thirdwx.qlogo.cn/mmopen/vi_32/t1IeXCJODYdTt2RPGqx2zDjVX4N1FrxCWqQFfico2wVfetel8vcQYax1ASJHagACzdGCiaUbzlbjjfwtZa5G5TSQ/132" width="30px"><span>yan_12345</span> 👍（2） 💬（1）<div>老师，在业务代码当中，在catch之后，在什么情况下需要重新抛出新的异常，这样做有什么意义和作用？</div>2020-04-17</li><br/><li><img src="https://static001.geekbang.org/account/avatar/00/11/bd/da/3d76ea74.jpg" width="30px"><span>看不到de颜色</span> 👍（1） 💬（1）<div>好文，目前生产环境就存在出现异常只向上返回e.getMessage()，导致出现预期外的问题时一脸懵逼，这块日后一定要注意。statis Exception这块学习到了，对日后闭坑有很大帮助。通过这篇文章还学到了try-with-resources语法，收货颇丰。</div>2020-04-11</li><br/><li><img src="https://static001.geekbang.org/account/avatar/00/0f/e5/c9/1061582b.jpg" width="30px"><span>skying</span> 👍（1） 💬（4）<div>你好，关于 提交到线程池的线程发生异常的场景。
我本地环境 添加了UncaughtExceptionHandler，但后续的5次循环中，打印的线程还是test1.

本地环境:spring boot2.2.5+undertow</div>2020-04-10</li><br/><li><img src="https://thirdwx.qlogo.cn/mmopen/vi_32/dgox0m94vr6w2Vxk0N6651pyL5wKWicqgwIxU9iahlIn5LKeFfQJDjzUoQKM8WNibS7Yuxyulmic1Xxfia5ibFc6ia0Hw/132" width="30px"><span>Geek_fe5e8a</span> 👍（0） 💬（1）<div>老师能不能讲讲lombok的注解@SneakyThrows </div>2020-09-01</li><br/><li><img src="" width="30px"><span>Geek_96815d</span> 👍（0） 💬（1）<div>execute 使用执行出现异常，程序依然没有中断</div>2020-07-07</li><br/><li><img src="https://static001.geekbang.org/account/avatar/00/11/a5/f0/8648c464.jpg" width="30px"><span>Joker</span> 👍（0） 💬（1）<div>   @GetMapping(&quot;wrong3&quot;)
    public void wrong3(@RequestParam(&quot;orderId&quot;) String orderId) {
        try {
            readFile();
        } catch (Exception e) {
            log.error(&quot;文件读取错误&quot;, e);
            throw new RuntimeException();
        }
    }

---
老师我在项目中发现这个也是错的，是因为用 `Exception` 代替了IOException吗？
还是因为抛出异常 throw new RuntimeException() 这里没有任何提示消息，所以是错误的用法？</div>2020-06-03</li><br/><li><img src="https://static001.geekbang.org/account/avatar/00/12/f5/57/ce10fb1b.jpg" width="30px"><span>天天向上</span> 👍（0） 💬（1）<div>老师，把异常定义为静态变量后，cancelOrderWrong的异常堆栈却是createOrderWrong的，是因为createOrderWrong的异常信息是先调用的，由于异常是staic的，导致之后所有该异常堆栈都是createOrderWrong的吗？</div>2020-05-17</li><br/><li><img src="https://static001.geekbang.org/account/avatar/00/12/06/08/855abb02.jpg" width="30px"><span>Seven.Lin澤耿</span> 👍（0） 💬（2）<div>老师，我想请假下你对Java中的Checked Exception和UnChecked Exception的看法？我个人编程习惯上不喜欢使用Checked Exception，我认为对编程不友好，而且无论出现什么异常都是对正常的逻辑造成影响，好像Checked Exception相对于UnChecked Exception没啥优点，有的话也就是告诉调用者有异常而已，但是异常还是得处理==、</div>2020-05-09</li><br/><li><img src="http://thirdwx.qlogo.cn/mmopen/vi_32/t1IeXCJODYdTt2RPGqx2zDjVX4N1FrxCWqQFfico2wVfetel8vcQYax1ASJHagACzdGCiaUbzlbjjfwtZa5G5TSQ/132" width="30px"><span>yan_12345</span> 👍（0） 💬（1）<div>老师，请教一个问题，在平常的业务代码当中，看到在catch异常之后，会抛出运行时异常RuntimeException，这种异常不是检查异常，不需要强制捕获，那重新抛出这种异常有什么作用，</div>2020-04-22</li><br/><li><img src="https://static001.geekbang.org/account/avatar/00/12/d1/3e/77c6ba5e.jpg" width="30px"><span>梁铁山</span> 👍（0） 💬（3）<div>老师好，我们项目是用SpringMVC的，也是使用统一异常处理，在实际项目中遇到了个比较棘手的问题。RespEntity&lt;Map&lt;String, String&gt;&gt; create(@RequestBody @Valid Useproduct useproduct, HttpServletRequest request) throws Exception { 。。。}  如果 MbeUserproduct 这个实体中的属性有@NotNull 等注解，那么通过添加@Valid可以在全局异常中捕获到属性异常信息（400）；如果属性中没有添加此类的注解，那么就不会进入全局的异常处理类中，前端虽然会收到400的响应状态，但是没有具体的错误信息。

老师，对于这类问题该怎么处理！</div>2020-04-20</li><br/><li><img src="https://static001.geekbang.org/account/avatar/00/10/10/bb/f1061601.jpg" width="30px"><span>Demon.Lee</span> 👍（0） 💬（2）<div>老师，关于java微服务之间通过rpc调用的异常处理问题，请教下，先说声谢谢。
我们使用了dubbo作为rpc调用的框架，但是微服务A调用微服务B时抛出了业务异常（比如xxxBusinessException），
这些异常都是微服务B自定义的（xxxBusinessException extends ApplicationException，而ApplicationException是extends RuntimeException），
但是返回到微服务A时，都被转成了RuntimeException。经查，是因为dubbo框架中通过ExceptionFilter把异常进行了处理，防止客户端无法识别而报错。
但是我其实想要的是这些异常里面的errorCode和errorMsg，现在都没有了。我现在有两种优化思路：
1. 微服务A和B都依赖这个ApplicationException，然后重写dubbo框架中的ExceptionFilter，抛出ApplicationException，
这样微服务A就可以通过这个异常获取到errorCode和errorMsg等信息；
2. 把RPC的返回结果由返回业务DTO，改成返回一个标准的APIResponse（即{&quot;success&quot;: false, &quot;data&quot;: 原来的业务DTO， &quot;errorCode&quot;：1111, &quot;errorMsg&quot;: &quot;xxxx&quot;}）;

老师觉得如何，有什么更好的行业实践么
</div>2020-04-10</li><br/><li><img src="https://static001.geekbang.org/account/avatar/00/11/62/d5/1f5c5ab6.jpg" width="30px"><span>大大大熊myeh</span> 👍（0） 💬（1）<div>关于“把异常定义为静态变量”的错误示例，建议把堆栈贴全，不要仅贴下半部分，可能是水平原因，我是运行了一下您的代码才理解后面的那段解释。

其实您想说的是，如果把异常定义为静态变量，那么以后每次调用这个静态变量的异常，它的堆栈信息都是第一次调用该异常时的堆栈信息，会引起排查时的很大困难。

（顺便测试一下留言的markdown）

````java
14:06:35.916 [main] ERROR org.geekbang.time.commonmistakes.exception.predefinedexception.PredefinedExceptionController - createOrder got error
org.geekbang.time.commonmistakes.exception.predefinedexception.BusinessException: 订单已经存在
	at org.geekbang.time.commonmistakes.exception.predefinedexception.Exceptions.&lt;clinit&gt;(Exceptions.java:5)
	at org.geekbang.time.commonmistakes.exception.predefinedexception.PredefinedExceptionController.createOrderWrong(PredefinedExceptionController.java:56)
	at org.geekbang.time.commonmistakes.exception.predefinedexception.PredefinedExceptionController.main(PredefinedExceptionController.java:29)
14:06:35.919 [main] ERROR org.geekbang.time.commonmistakes.exception.predefinedexception.PredefinedExceptionController - cancelOrder got error
org.geekbang.time.commonmistakes.exception.predefinedexception.BusinessException: 订单已经存在
	at org.geekbang.time.commonmistakes.exception.predefinedexception.Exceptions.&lt;clinit&gt;(Exceptions.java:5)
	at org.geekbang.time.commonmistakes.exception.predefinedexception.PredefinedExceptionController.createOrderWrong(PredefinedExceptionController.java:56)
	at org.geekbang.time.commonmistakes.exception.predefinedexception.PredefinedExceptionController.main(PredefinedExceptionController.java:29)
````
</div>2020-04-10</li><br/><li><img src="http://thirdwx.qlogo.cn/mmopen/vi_32/bvj76PmeUvW8kokyu91IZWuRATKmabibDWbzAj2TajeEic7WvKCJOLaOh6jibEmdQ36EO3sBUZ0HibAiapsrZo64U8w/132" width="30px"><span>梦倚栏杆</span> 👍（6） 💬（0）<div>现在出问题就是瞎子，一点一点的日志的打，上线，哎，这哪是个合格的RD呀</div>2020-04-04</li><br/><li><img src="https://static001.geekbang.org/account/avatar/00/14/64/79/f1e1ca76.jpg" width="30px"><span>努力奋斗的Pisces</span> 👍（4） 💬（0）<div>1.得看finally里面是怎么处理的了，除非finally没有执行到，或者是finally里面报错了，不然都是按照finally里面的返回值做最终的返回吧</div>2020-04-04</li><br/><li><img src="https://static001.geekbang.org/account/avatar/00/0f/a1/e6/50da1b2d.jpg" width="30px"><span>旭东(Frank)</span> 👍（3） 💬（0）<div>订单存在异常，这个例子实际开发中真需要区分吗？个人觉得无效参数的例子更好些</div>2020-04-04</li><br/><li><img src="https://thirdwx.qlogo.cn/mmopen/vi_32/L8EpqHoAnmvkzCIsdOkv5QvhIzu5tMaF2FDusXShqukv5ZBkS8DbicWaErjnYydibiaqBrs70wQ8P6axvC2FbWpbQ/132" width="30px"><span>Geek_d3928c</span> 👍（1） 💬（0）<div>try-with-resources语句能够帮你自动调用资源的close()函数关闭资源不用到finally块.,在try关键字后面的( )里new一些需要自动关闭的资源。</div>2022-07-07</li><br/><li><img src="https://thirdwx.qlogo.cn/mmopen/vi_32/Q0j4TwGTfTIV7iaia7Ko59UJk3oap1XZEg6JW999tIibuTicWfVXgaXicUHjABI6ibXErd2tY527VMsib5ElZJxSW8nFw/132" width="30px"><span>刘志鹏</span> 👍（1） 💬（0）<div>我的异常处理通常这么做：1： 自定义异常，包括中英文message, code。2： service手动抛出业务异常， controller 不捕获； 3：框架统一处理。

这样返回的message，其实也是service抛出的异常消息。  </div>2021-10-30</li><br/><li><img src="http://thirdwx.qlogo.cn/mmopen/vi_32/DYAIOgq83ersGSic8ib7OguJv6CJiaXY0s4n9C7Z51sWxTTljklFpq3ZAIWXoFTPV5oLo0GMTkqW5sYJRRnibNqOJQ/132" width="30px"><span>walle斌</span> 👍（1） 💬（0）<div>没有回答老师的问题，而是对异常处理有一些其他看法
1、log.error保留现场，log.error(&quot;xxx error:&quot; + reqString,e)
2、以标准返回，返回错误，供上层处理，按照标准返回的正确与与否返回
3、标准返回，除了一般的是否正确，错误码，错误信息，增加如下2点，方便快速排查问题
1）、详细错误，附带错误的前200【可配置】信息，且对外网关可以考虑过滤此字段
2）、全链路跟踪字段
直接把全链路跟踪字段暴露出来，对于异常排场加速排查。而且有了详细错误字段，其实一眼就能看出咋回事了，一般的错误。</div>2021-07-05</li><br/><li><img src="https://static001.geekbang.org/account/avatar/00/38/fa/76/561eeaa3.jpg" width="30px"><span>S</span> 👍（0） 💬（0）<div>如果使用Executors.newScheduledThreadPool创建的线程池情况，程序异常时也是有坑的</div>2023-10-24</li><br/><li><img src="https://static001.geekbang.org/account/avatar/00/12/10/6e/a21968a9.jpg" width="30px"><span>花下眠</span> 👍（0） 💬（0）<div>异常以为自己理解了，看完这节课，收获满满，瑞思拜
1、切记生吞异常，并且记录堆栈信息
2、异常消息有意义
3、异常覆盖
4、线程池异常，为线程起名字好定位问题，注意异常后线程是否退出等</div>2022-01-27</li><br/><li><img src="https://static001.geekbang.org/account/avatar/00/11/99/af/d29273e2.jpg" width="30px"><span>饭粒</span> 👍（0） 💬（0）<div>为什么我测试时，execute 方式即使加了异常捕获处理，线程还是会退出重建？</div>2021-10-09</li><br/><li><img src="https://thirdwx.qlogo.cn/mmopen/vi_32/X4ib36ADEvj76XaKD4OUY9k15KqWCAVCwibPicBxz6BBUfDrVolpYInn8zFOw3JBPtVw3L4Lkibaf2eLPemwGKzAXA/132" width="30px"><span>Geek_427d0c</span> 👍（0） 💬（0）<div>不知道是什么原因，下述代码，没有出现老师的静态Exception的现象。打印的error堆栈信息看到还是很正常的。
package com.example.demo;

import lombok.extern.slf4j.Slf4j;

&#47;**
 * Created by wensi on 2021-09-09
 *&#47;
@Slf4j
public class Test {
    public static BusinessException ORDEREXISTS = new BusinessException(&quot;订单已经存在&quot;);

    public static void main(String[] args) throws InterruptedException {
        new Test().wrong();
    }

    public void wrong() {
        try {
            createOrderWrong();
        } catch (Exception ex) {
            log.error(&quot;createOrder got error&quot;, ex);
        }
        try {
            cancelOrderWrong();
        } catch (Exception ex) {
            log.error(&quot;cancelOrder got error&quot;, ex);
        }
    }

    private void createOrderWrong() { &#47;&#47;这里有问题
        throw Test.ORDEREXISTS;
    }

    private void cancelOrderWrong() { &#47;&#47;这里有问题
        throw Test.ORDEREXISTS;
    }
}
</div>2021-09-29</li><br/><li><img src="https://static001.geekbang.org/account/avatar/00/29/0b/44/c6487b93.jpg" width="30px"><span>Vince</span> 👍（0） 💬（0）<div>真好，受益匪浅，直接就读了2遍，我还得和小伙伴分享一下收获</div>2021-08-26</li><br/>
</ul>